Workbook

Sheet Рынок+ ИНФО(если не подтягивает
F1: 2013 | G1: 2014 | H1: 2015 | I1: 2016 | J1: 2017 | K1: 2018 | L1: 2019 | M1: 2020 | N1: 2021 | O1: 2022 | P1: 2023 | Q1: 2024 | R1: 2025
A2: Регион | B2: Субъект | C2: Город | D2: Население в городе | E2: Заработная плата (Руб) | F2: ='[1]рост год к году+Об рынка+конкур'!G29 -> Объем Рынка (тыс. Руб с НДС) 2013 | G2: ='[1]рост год к году+Об рынка+конкур'!H29 -> Объем Рынка (тыс. Руб с НДС) 2014 | H2: ='[1]рост год к году+Об рынка+конкур'!I29 -> Объем Рынка (тыс. Руб с НДС) 2015 | I2: Объем Рынка (тыс. Руб с НДС) 2016 | J2: Объем Рынка (тыс. Руб с НДС) 2017 | K2: Объем Рынка (тыс. Руб с НДС) 2018 | L2: Объем Рынка (тыс. Руб с НДС) 2019 | M2: Объем Рынка (тыс. Руб с НДС) 2020 | N2: Объем Рынка (тыс. Руб с НДС) 2021 | O2: Объем Рынка (тыс. Руб с НДС) 2022 | P2: Объем Рынка (тыс. Руб с НДС) 2023 | Q2: Объем Рынка (тыс. Руб с НДС) 2024 | R2: Объем Рынка (тыс. Руб с НДС) 2025
A3: CENTRAL | B3: Белгородская область | C3: Алексеевка | D3: 38979 | E3: 21716.116 | F3: 467012.6 | G3: 464404.99 | H3: 456704.73 | I3: 457432.06 | J3: 462006.38 | K3: 475866.57 | L3: 490142.57 | M3: 504846.85 | N3: 519992.25 | O3: 535592.02 | P3: 551659.78 | Q3: 568209.57 | R3: 585255.86
A4: CENTRAL | B4: Белгородская область | C4: Белгород | D4: 373528 | E4: 26168.773 | F4: 5392899.1 | G4: 5362787.2 | H4: 5273867.3 | I4: 5282266.3 | J4: 5335088.9 | K4: 5495141.6 | L4: 5659995.8 | M4: 5829795.7 | N4: 6004689.6 | O4: 6184830.3 | P4: 6370375.2 | Q4: 6561486.4 | R4: 6758331
A5: CENTRAL | B5: Белгородская область | C5: Валуйки | D5: 34627 | E5: 20905.98 | F5: 399393.66 | G5: 397163.6 | H5: 390578.26 | I5: 391200.28 | J5: 395112.29 | K5: 406965.65 | L5: 419174.62 | M5: 431749.86 | N5: 444702.36 | O5: 458043.43 | P5: 471784.73 | Q5: 485938.27 | R5: 500516.42
A6: CENTRAL | B6: Белгородская область | C6: Губкин | D6: 87556 | E6: 25184.394 | F6: 1216559 | G6: 1209766.2 | H6: 1189707.2 | I6: 1191601.9 | J6: 1203517.9 | K6: 1239623.4 | L6: 1276812.1 | M6: 1315116.5 | N6: 1354570 | O6: 1395207.1 | P6: 1437063.3 | Q6: 1480175.2 | R6: 1524580.5
A7: CENTRAL | B7: Белгородская область | C7: Старый Оскол | D7: 220816 | E7: 25138.737 | F7: 3062596.3 | G7: 3045496 | H7: 2994998.9 | I7: 2999768.6 | J7: 3029766.3 | K7: 3120659.3 | L7: 3214279 | M7: 3310707.4 | N7: 3410028.6 | O7: 3512329.5 | P7: 3617699.4 | Q7: 3726230.4 | R7: 3838017.3
A8: CENTRAL | B8: Белгородская область | C8: Строитель | D8: 24260 | E8: 21039.499 | F8: 281606.03 | G8: 280033.65 | H8: 275390.44 | I8: 275829.02 | J8: 278587.31 | K8: 286944.93 | L8: 295553.27 | M8: 304419.87 | N8: 313552.47 | O8: 322959.04 | P8: 332647.81 | Q8: 342627.25 | R8: 352906.06
A9: CENTRAL | B9: Белгородская область | C9: Шебекино | D9: 43786 | E9: 19059.079 | F9: 460418.69 | G9: 457847.89 | H9: 450256.35 | I9: 450973.42 | J9: 455483.15 | K9: 469147.65 | L9: 483222.08 | M9: 497718.74 | N9: 512650.3 | O9: 528029.81 | P9: 543870.7 | Q9: 560186.82 | R9: 576992.43
A10: CENTRAL | B10: Брянская область | C10: Брянск | D10: 410837 | E10: 24168.672 | F10: 3866263.3 | G10: 3938280.4 | H10: 3967435.4 | I10: 3973753.8 | J10: 4013491.3 | K10: 4133896 | L10: 4257912.9 | M10: 4385650.3 | N10: 4517219.8 | O10: 4652736.4 | P10: 4792318.5 | Q10: 4936088.1 | R10: 5084170.7
A11: CENTRAL | B11: Брянская область | C11: Дятьково | D11: 28141 | E11: 16320.546 | F11: 178831.21 | G11: 182162.31 | H11: 183510.85 | I11: 183803.1 | J11: 185641.13 | K11: 191210.37 | L11: 196946.68 | M11: 202855.08 | N11: 208940.73 | O11: 215208.95 | P11: 221665.22 | Q11: 228315.18 | R11: 235164.63
A12: CENTRAL | B12: Брянская область | C12: Клинцы | D12: 61515 | E12: 15883.595 | F12: 760902.32 | G12: 775075.69 | H12: 780813.55 | I12: 782057.05 | J12: 789877.62 | K12: 813573.94 | L12: 837981.16 | M12: 863120.6 | N12: 889014.22 | O12: 915684.64 | P12: 943155.18 | Q12: 971449.84 | R12: 1000593.3
A13: CENTRAL | B13: Брянская область | C13: Новозыбков | D13: 40499 | E13: 15388.68 | F13: 242669.25 | G13: 247189.47 | H13: 249019.4 | I13: 249415.98 | J13: 251910.14 | K13: 259467.45 | L13: 267251.47 | M13: 275269.01 | N13: 283527.08 | O13: 292032.9 | P13: 300793.88 | Q13: 309817.7 | R13: 319112.23
A14: CENTRAL | B14: Брянская область | C14: Унеча | D14: 25412 | E14: 19785.271 | F14: 195771.71 | G14: 199418.36 | H14: 200894.65 | I14: 201214.58 | J14: 203226.73 | K14: 209323.53 | L14: 215603.24 | M14: 222071.34 | N14: 228733.48 | O14: 235595.48 | P14: 242663.34 | Q14: 249943.24 | R14: 257441.54
... A659: URAL | B659: Ямало-Ненецкий автономный округ | C659: Тарко-Сале | D659: 20906 | E659: 70509.707 | F659: 457880.39 | G659: 418163.48 | H659: 392821.22 | I659: 392821.22 | J659: 396749.43 | K659: 408651.92 | L659: 420911.48 | M659: 433538.82 | N659: 446544.98 | O659: 459941.33 | P659: 473739.57 | Q659: 487951.76 | R659: 502590.31

Sheet Города зп новое (без мск.об)
A1: Область | B1: Города присутствия | C1: Ср зп 2014 | D1: =D2+1 -> 1069
A2: Алтайский край | B2: Барнаул | C2: 25286.412 | D2: =D3+1 -> 1068
A3: Алтайский край | B3: Бийск | C3: 20153.677 | D3: =D4+1 -> 1067
A4: Алтайский край | B4: Рубцовск | C4: 18959.454 | D4: =D5+1 -> 1066
A5: Алтайский край | B5: Новоалтайск | C5: 23957.618 | D5: =D6+1 -> 1065
A6: Алтайский край | B6: Заринск | C6: 24325.781 | D6: =D7+1 -> 1064
A7: Алтайский край | B7: Камень-на-Оби | C7: 17870.733 | D7: =D8+1 -> 1063
A8: Алтайский край | B8: Славгород | C8: 17514.964 | D8: =D9+1 -> 1062
A9: Алтайский край | B9: Алейск | C9: 18944.848 | D9: =D10+1 -> 1061
A10: Алтайский край | B10: Яровое | C10: 16843.971 | D10: =D11+1 -> 1060
A11: Алтайский край | B11: Белокуриха | C11: 24111.2 | D11: =D12+1 -> 1059
A12: Алтайский край | B12: Горняк | C12: 16685.877 | D12: =D13+1 -> 1058
A13: Алтайский край | B13: Змеиногорск | C13: 16795.401 | D13: =D14+1 -> 1057
... A27: Архангельская область | B27: Коряжма | C27: 32773.365 | D27: =D28+1 -> 1043
A28: Архангельская область | B28: Мирный | D28: =D29+1 -> 1042
A29: Архангельская область | B29: Вельск‎ | C29: 28872.089 | D29: =D30+1 -> 1041
A30: Архангельская область | B30: Нарьян-Мар | C30: 64320.828 | D30: =D31+1 -> 1040
A31: Архангельская область | B31: Няндома | C31: 34403.677 | D31: =D32+1 -> 1039
A32: Архангельская область | B32: Онега‎ | C32: 29220.974 | D32: =D33+1 -> 1038
A33: Архангельская область | B33: Каргополь‎ | C33: 23342.926 | D33: =D34+1 -> 1037
A34: Архангельская область | B34: Шенкурск | C34: 25735.543 | D34: =D35+1 -> 1036
A35: Архангельская область | B35: Мезень | C35: 41470.275 | D35: =D36+1 -> 1035
A36: Архангельская область | B36: Сольвычегодск | C36: 35321.852 | D36: =D37+1 -> 1034
A37: Астраханская область | B37: Астрахань | C37: 28349.427 | D37: =D38+1 -> 1033
A38: Астраханская область | B38: Ахтубинск | C38: 18654.275 | D38: =D39+1 -> 1032
A39: Астраханская область | B39: Знаменск | D39: =D40+1 -> 1031
A40: Астраханская область | B40: Харабали | C40: 17437.364 | D40: =D41+1 -> 1030
A41: Астраханская область | B41: Камызяк | C41: 15803.956 | D41: =D42+1 -> 1029
A42: Астраханская область | B42: Нариманов | C42: 21855.098 | D42: =D43+1 -> 1028
A43: Белгородская область | B43: Белгород | C43: 27611.973 | D43: =D44+1 -> 1027
A44: Белгородская область | B44: Старый Оскол | C44: 26483.78 | D44: =D45+1 -> 1026
A45: Белгородская область | B45: Губкин | C45: 27743.332 | D45: =D46+1 -> 1025
A46: Белгородская область | B46: Шебекино | C46: 22173.889 | D46: =D47+1 -> 1024
A47: Белгородская область | B47: Алексеевка | C47: 23944.861 | D47: =D48+1 -> 1023
A48: Белгородская область | B48: Валуйки | C48: 20458.314 | D48: =D49+1 -> 1022
A49: Белгородская область | B49: Строитель | C49: 23766.566 | D49: =D50+1 -> 1021
A50: Белгородская область | B50: Новый Оскол | C50: 22436.144 | D50: =D51+1 -> 1020
A51: Белгородская область | B51: Бирюч | C51: 21508.268 | D51: =D52+1 -> 1019
... A79: Владимирская область | B79: Собинка | C79: 27738.137 | D79: =D80+1 -> 991
A80: Владимирская область | B80: Радужный | D80: =D81+1 -> 990
...

Sheet Лист1
A1: id | B1: name | C1: descr | D1: scale1 | E1: scale2 | F1: lonlatarr | G1: lonL | H1: latT | I1: LonR | J1: LatB | K1: color1 | L1: color2 | M1: visible | N1: picname | O1: categoryid | P1: Фильтр для карт
A2: =старый!G2 -> 8880001 | B2: =старый!D2 -> Алексеевка(38626) | C2: =A2&";"&B2&";"&Q2&";"&"население 2014-2015 год" -> 8880001;Алексеевка(38626);Белгородская область;население 2014-2015 год | D2: 15 | E2: 20 | G2: =старый!E2 -> 38.688095 | H2: =старый!F2 -> 50.629961 | I2: =G2 -> 38.688095 | J2: =H2 -> 50.629961 | K2: -500000000 | L2: -1509949440 | M2: TRUE | N2: wht-stars.png | O2: 888 | P2: 1 | Q2: =старый!A2 -> Белгородская область
A3: =старый!G3 -> 8880002 | B3: =старый!D3 -> Белгород(384425) | C3: =A3&";"&B3&";"&Q3&";"&"население 2014-2015 год" -> 8880002;Белгород(384425);Белгородская область;население 2014-2015 год | D3: 15 | E3: 20 | G3: =старый!E3 -> 36.588849 | H3: =старый!F3 -> 50.597467 | I3: =G3 -> 36.588849 | J3: =H3 -> 50.597467 | K3: -500000000 | L3: -1509949440 | M3: TRUE | N3: wht-stars.png | O3: 888 | P3: 1 | Q3: =старый!A3 -> Белгородская область
A4: =старый!G4 -> 8880003 | B4: =старый!D4 -> Валуйки(34296) | C4: =A4&";"&B4&";"&Q4&";"&"население 2014-2015 год" -> 8880003;Валуйки(34296);Белгородская область;население 2014-2015 год | D4: 15 | E4: 20 | G4: =старый!E4 -> 38.099914 | H4: =старый!F4 -> 50.211194 | I4: =G4 -> 38.099914 | J4: =H4 -> 50.211194 | K4: -500000000 | L4: -1509949440 | M4: TRUE | N4: wht-stars.png | O4: 888 | P4: 1 | Q4: =старый!A4 -> Белгородская область
A5: =старый!G5 -> 8880004 | B5: =старый!D5 -> Губкин(87405) | C5: =A5&";"&B5&";"&Q5&";"&"население 2014-2015 год" -> 8880004;Губкин(87405);Белгородская область;население 2014-2015 год | D5: 15 | E5: 20 | G5: =старый!E5 -> 37.534748 | H5: =старый!F5 -> 51.283644 | I5: =G5 -> 37.534748 | J5: =H5 -> 51.283644 | K5: -500000000 | L5: -1509949440 | M5: TRUE | N5: wht-stars.png | O5: 888 | P5: 1 | Q5: =старый!A5 -> Белгородская область
A6: =старый!G6 -> 8880005 | B6: =старый!D6 -> Старый Оскол(221254) | C6: =A6&";"&B6&";"&Q6&";"&"население 2014-2015 год" -> 8880005;Старый Оскол(221254);Белгородская область;население 2014-2015 год | D6: 15 | E6: 20 | G6: =старый!E6 -> 37.835054 | H6: =старый!F6 -> 51.296695 | I6: =G6 -> 37.835054 | J6: =H6 -> 51.296695 | K6: -500000000 | L6: -1509949440 | M6: TRUE | N6: wht-stars.png | O6: 888 | P6: 1 | Q6: =старый!A6 -> Белгородская область
A7: =старый!G7 -> 8880006 | B7: =старый!D7 -> Строитель(24185) | C7: =A7&";"&B7&";"&Q7&";"&"население 2014-2015 год" -> 8880006;Строитель(24185);Белгородская область;население 2014-2015 год | D7: 15 | E7: 20 | G7: =старый!E7 -> 36.488686 | H7: =старый!F7 -> 50.784551 | I7: =G7 -> 36.488686 | J7: =H7 -> 50.784551 | K7: -500000000 | L7: -1509949440 | M7: TRUE | N7: wht-stars.png | O7: 888 | P7: 1 | Q7: =старый!A7 -> Белгородская область
A8: =старый!G8 -> 8880007 | B8: =старый!D8 -> Шебекино(43331) | C8: =A8&";"&B8&";"&Q8&";"&"население 2014-2015 год" -> 8880007;Шебекино(43331);Белгородская область;население 2014-2015 год | D8: 15 | E8: 20 | G8: =старый!E8 -> 36.887871 | H8: =старый!F8 -> 50.400498 | I8: =G8 -> 36.887871 | J8: =H8 -> 50.400498 | K8: -500000000 | L8: -1509949440 | M8: TRUE | N8: wht-stars.png | O8: 888 | P8: 1 | Q8: =старый!A8 -> Белгородская область
A9: =старый!G9 -> 8880008 | B9: =старый!D9 -> Брянск(426060) | C9: =A9&";"&B9&";"&Q9&";"&"население 2014-2015 год" -> 8880008;Брянск(426060);Брянская область;население 2014-2015 год | D9: 15 | E9: 20 | G9: =старый!E9 -> 34.363731 | H9: =старый!F9 -> 53.243325 | I9: =G9 -> 34.363731 | J9: =H9 -> 53.243325 | K9: -500000000 | L9: -1509949440 | M9: TRUE | N9: wht-stars.png | O9: 888 | P9: 1 | Q9: =старый!A9 -> Брянская область
A10: =старый!G10 -> 8880009 | B10: =старый!D10 -> Дятьково(27535) | C10: =A10&";"&B10&";"&Q10&";"&"население 2014-2015 год" -> 8880009;Дятьково(27535);Брянская область;население 2014-2015 год | D10: 15 | E10: 20 | G10: =старый!E10 -> 34.339656 | H10: =старый!F10 -> 53.597306 | I10: =G10 -> 34.339656 | J10: =H10 -> 53.597306 | K10: -500000000 | L10: -1509949440 | M10: TRUE | N10: wht-stars.png | O10: 888 | P10: 1 | Q10: =старый!A10 -> Брянская область
A11: =старый!G11 -> 8880010 | B11: =старый!D11 -> Клинцы(69181) | C11: =A11&";"&B11&";"&Q11&";"&"население 2014-2015 год" -> 8880010;Клинцы(69181);Брянская область;население 2014-2015 год | D11: 15 | E11: 20 | G11: =старый!E11 -> 32.233861 | H11: =старый!F11 -> 52.752816 | I11: =G11 -> 32.233861 | J11: =H11 -> 52.752816 | K11: -500000000 | L11: -1509949440 | M11: TRUE | N11: wht-stars.png | O11: 888 | P11: 1 | Q11: =старый!A11 -> Брянская область
A12: =старый!G12 -> 8880011 | B12: =старый!D12 -> Новозыбков(40765) | C12: =A12&";"&B12&";"&Q12&";"&"население 2014-2015 год" -> 8880011;Новозыбков(40765);Брянская область;население 2014-2015 год | D12: 15 | E12: 20 | G12: =старый!E12 -> 31.933446 | H12: =старый!F12 -> 52.536016 | I12: =G12 -> 31.933446 | J12: =H12 -> 52.536016 | K12: -500000000 | L12: -1509949440 | M12: TRUE | N12: wht-stars.png | O12: 888 | P12: 1 | Q12: =старый!A12 -> Брянская область
A13: =старый!G13 -> 8880012 | B13: =старый!D13 -> Унеча(24639) | C13: =A13&";"&B13&";"&Q13&";"&"население 2014-2015 год" -> 8880012;Унеча(24639);Брянская область;население 2014-2015 год | D13: 15 | E13: 20 | G13: =старый!E13 -> 32.681051 | H13: =старый!F13 -> 52.847791 | I13: =G13 -> 32.681051 | J13: =H13 -> 52.847791 | K13: -500000000 | L13: -1509949440 | M13: TRUE | N13: wht-stars.png | O13: 888 | P13: 1 | Q13: =старый!A13 -> Брянская область
... A658: =старый!G658 -> 8880657 | B658: =старый!D658 -> Тарко-Сале(21304) | C658: =A658&";"&B658&";"&Q658&";"&"население 2014-2015 год" -> 8880657;Тарко-Сале(21304);Ямало-Ненецкий автономный округ;население 2014-2015 год | D658: 15 | E658: 20 | G658: =старый!E658 -> 77.761055 | H658: =старый!F658 -> 64.911819 | I658: =G658 -> 77.761055 | J658: =H658 -> 64.911819 | K658: -500000000 | L658: -1509949440 | M658: TRUE | N658: wht-stars.png | O658: 888 | P658: 1 | Q658: =старый!A658 -> Ямало-Ненецкий автономный округ

Sheet старый
A1: address | C1: население | D1: город+ население | E1: dolgota | F1: shirota | G1: ID | H1: id конкур | I1: Код Номер
A2: Белгородская область | B2: Алексеевка | C2: =VLOOKUP(B2,'население 2014'!C:D,2,0) -> 38626 | D2: =B2&"("&C2&")" -> Алексеевка(38626) | E2: 38.688095 | F2: 50.629961 | G2: =H2*10000+I2 -> 8880001 | H2: 888 | I2: 1
A3: Белгородская область | B3: Белгород | C3: =VLOOKUP(B3,'население 2014'!C:D,2,0) -> 384425 | D3: =B3&"("&C3&")" -> Белгород(384425) | E3: 36.588849 | F3: 50.597467 | G3: =H3*10000+I3 -> 8880002 | H3: 888 | I3: 2
A4: Белгородская область | B4: Валуйки | C4: =VLOOKUP(B4,'население 2014'!C:D,2,0) -> 34296 | D4: =B4&"("&C4&")" -> Валуйки(34296) | E4: 38.099914 | F4: 50.211194 | G4: =H4*10000+I4 -> 8880003 | H4: 888 | I4: 3
A5: Белгородская область | B5: Губкин | C5: =VLOOKUP(B5,'население 2014'!C:D,2,0) -> 87405 | D5: =B5&"("&C5&")" -> Губкин(87405) | E5: 37.534748 | F5: 51.283644 | G5: =H5*10000+I5 -> 8880004 | H5: 888 | I5: 4
A6: Белгородская область | B6: Старый Оскол | C6: =VLOOKUP(B6,'население 2014'!C:D,2,0) -> 221254 | D6: =B6&"("&C6&")" -> Старый Оскол(221254) | E6: 37.835054 | F6: 51.296695 | G6: =H6*10000+I6 -> 8880005 | H6: 888 | I6: 5
A7: Белгородская область | B7: Строитель | C7: =VLOOKUP(B7,'население 2014'!C:D,2,0) -> 24185 | D7: =B7&"("&C7&")" -> Строитель(24185) | E7: 36.488686 | F7: 50.784551 | G7: =H7*10000+I7 -> 8880006 | H7: 888 | I7: 6
A8: Белгородская область | B8: Шебекино | C8: =VLOOKUP(B8,'население 2014'!C:D,2,0) -> 43331 | D8: =B8&"("&C8&")" -> Шебекино(43331) | E8: 36.887871 | F8: 50.400498 | G8: =H8*10000+I8 -> 8880007 | H8: 888 | I8: 7
A9: Брянская область | B9: Брянск | C9: =VLOOKUP(B9,'население 2014'!C:D,2,0) -> 426060 | D9: =B9&"("&C9&")" -> Брянск(426060) | E9: 34.363731 | F9: 53.243325 | G9: =H9*10000+I9 -> 8880008 | H9: 888 | I9: 8
A10: Брянская область | B10: Дятьково | C10: =VLOOKUP(B10,'население 2014'!C:D,2,0) -> 27535 | D10: =B10&"("&C10&")" -> Дятьково(27535) | E10: 34.339656 | F10: 53.597306 | G10: =H10*10000+I10 -> 8880009 | H10: 888 | I10: 9
A11: Брянская область | B11: Клинцы | C11: =VLOOKUP(B11,'население 2014'!C:D,2,0) -> 69181 | D11: =B11&"("&C11&")" -> Клинцы(69181) | E11: 32.233861 | F11: 52.752816 | G11: =H11*10000+I11 -> 8880010 | H11: 888 | I11: 10
A12: Брянская область | B12: Новозыбков | C12: =VLOOKUP(B12,'население 2014'!C:D,2,0) -> 40765 | D12: =B12&"("&C12&")" -> Новозыбков(40765) | E12: 31.933446 | F12: 52.536016 | G12: =H12*10000+I12 -> 8880011 | H12: 888 | I12: 11
A13: Брянская область | B13: Унеча | C13: =VLOOKUP(B13,'население 2014'!C:D,2,0) -> 24639 | D13: =B13&"("&C13&")" -> Унеча(24639) | E13: 32.681051 | F13: 52.847791 | G13: =H13*10000+I13 -> 8880012 | H13: 888 | I13: 12
... A658: Ямало-Ненецкий автономный округ | B658: Тарко-Сале | C658: =VLOOKUP(B658,'население 2014'!C:D,2,0) -> 21304 | D658: =B658&"("&C658&")" -> Тарко-Сале(21304) | E658: 77.761055 | F658: 64.911819 | G658: =H658*10000+I658 -> 8880657 | H658: 888 | I658: 657

Sheet население 2014
A1: Регион | B1: Субъект | C1: Город | D1: Население 2014 | E1: Население в городе 2013
A2: CENTRAL | B2: Белгородская область | C2: Алексеевка | D2: 38626 | E2: 38979
A3: CENTRAL | B3: Белгородская область | C3: Белгород | D3: 384425 | E3: 373528
A4: CENTRAL | B4: Белгородская область | C4: Валуйки | D4: 34296 | E4: 34627
A5: CENTRAL | B5: Белгородская область | C5: Губкин | D5: 87405 | E5: 87556
A6: CENTRAL | B6: Белгородская область | C6: Старый Оскол | D6: 221254 | E6: 220816
A7: CENTRAL | B7: Белгородская область | C7: Строитель | D7: 24185 | E7: 24260
A8: CENTRAL | B8: Белгородская область | C8: Шебекино | D8: 43331 | E8: 43786
A9: CENTRAL | B9: Брянская область | C9: Брянск | D9: 426060 | E9: 410837
A10: CENTRAL | B10: Брянская область | C10: Дятьково | D10: 27535 | E10: 28141
A11: CENTRAL | B11: Брянская область | C11: Клинцы | D11: 69181 | E11: 61515
A12: CENTRAL | B12: Брянская область | C12: Новозыбков | D12: 40765 | E12: 40499
A13: CENTRAL | B13: Брянская область | C13: Унеча | D13: 24639 | E13: 25412
... A455: SIBERIA | B455: Омская область | C455: Исилькуль | D455: 23865 | E455: 24196
A456: SIBERIA | B456: Омская область | C456: Калачинск | D456: 22 656 | E456: 22915
A457: SIBERIA | B457: Омская область | C457: Омск | D457: 1173854 | E457: 1160670
A458: SIBERIA | B458: Омская область | C458: Тара | D458: 27922 | E458: 27740
A459: SIBERIA | B459: Республика Алтай | C459: Горно-Алтайск | D459: 62309 | E459: 60828
A460: SIBERIA | B460: Республика Бурятия | C460: Гусиноозерск | D460: 23 307 | E460: 23781
A461: SIBERIA | B461: Республика Бурятия | C461: Северобайкальск | D461: 24 101 | E461: 24449
A462: SIBERIA | B462: Республика Бурятия | C462: Улан-Удэ | D462: 426 650 | E462: 416079
A463: SIBERIA | B463: Республика Тыва | C463: Кызыл | D463: 114181 | E463: 113333
A464: SIBERIA | B464: Республика Хакасия | C464: Абакан | D464: 176200 | E464: 169760
A465: SIBERIA | B465: Республика Хакасия | C465: Саяногорск | D465: 48851 | E465: 48942
A466: SIBERIA | B466: Республика Хакасия | C466: Черногорск | D466: 73187 | E466: 72599
A467: SIBERIA | B467: Томская область | C467: Асино | D467: 24619 | E467: 24837
A468: SIBERIA | B468: Томская область | C468: Колпашево | D468: 23044 | E468: 23188
A469: SIBERIA | B469: Томская область | C469: Северск | D469: 108407 | E469: 109594
A470: SIBERIA | B470: Томская область | C470: Стрежевой | D470: 41743 | E470: 41688
A471: SIBERIA | B471: Томская область | C471: Томск | D471: 564910 | E471: 547989
A472: SOUTHERN | B472: Астраханская область | C472: Астрахань | D472: 532699 | E472: 527345
A473: SOUTHERN | B473: Астраханская область | C473: Ахтубинск | D473: 38507 | E473: 39386
A474: SOUTHERN | B474: Астраханская область | C474: Знаменск | D474: 27021 | E474: 27526
... A658: URAL | B658: Ямало-Ненецкий автономный округ | C658: Тарко-Сале | D658: 21304 | E658: 20906

Sheet зп+население
A1: address | B1: dolgota | C1: shirota | E1: население | F1: зп новое 2014 | G1: зп из розницы
A2: Алтайский край | B2: Барнаул | C2: 83.779875 | D2: 53.348053 | E2: =VLOOKUP(B2,'население 2014'!C:D,2,0) -> 655656 | F2: =VLOOKUP(B2,'Города зп новое (без мск.об)'!B:C,2,0) -> 25286.412 | G2: =IF(F2=0,VLOOKUP(B2,'Рынок+ ИНФО(если не подтягивает'!C:E,3,0),0) -> 0
A3: Алтайский край | B3: Бийск | C3: 85.213829 | D3: 52.539308 | E3: =VLOOKUP(B3,'население 2014'!C:D,2,0) -> 204164 | F3: =VLOOKUP(B3,'Города зп новое (без мск.об)'!B:C,2,0) -> 20153.677 | G3: =IF(F3=0,VLOOKUP(B3,'Рынок+ ИНФО(если не подтягивает'!C:E,3,0),0) -> 0
A4: Алтайский край | B4: Рубцовск | C4: 81.207774 | D4: 51.501235 | E4: =VLOOKUP(B4,'население 2014'!C:D,2,0) -> 146516 | F4: =VLOOKUP(B4,'Города зп новое (без мск.об)'!B:C,2,0) -> 18959.454 | G4: =IF(F4=0,VLOOKUP(B4,'Рынок+ ИНФО(если не подтягивает'!C:E,3,0),0) -> 0
A5: Алтайский край | B5: Новоалтайск | C5: 83.931052 | D5: 53.412058 | E5: =VLOOKUP(B5,'население 2014'!C:D,2,0) -> 72308 | F5: =VLOOKUP(B5,'Города зп новое (без мск.об)'!B:C,2,0) -> 23957.618 | G5: =IF(F5=0,VLOOKUP(B5,'Рынок+ ИНФО(если не подтягивает'!C:E,3,0),0) -> 0
A6: Алтайский край | B6: Заринск | C6: 84.931551 | D6: 53.706332 | E6: =VLOOKUP(B6,'население 2014'!C:D,2,0) -> 47274 | F6: =VLOOKUP(B6,'Города зп новое (без мск.об)'!B:C,2,0) -> 24325.781 | G6: =IF(F6=0,VLOOKUP(B6,'Рынок+ ИНФО(если не подтягивает'!C:E,3,0),0) -> 0
A7: Алтайский край | B7: Камень-на-Оби | C7: 81.354603 | D7: 53.79147 | E7: =VLOOKUP(B7,'население 2014'!C:D,2,0) -> 41897 | F7: =VLOOKUP(B7,'Города зп новое (без мск.об)'!B:C,2,0) -> 17870.733 | G7: =IF(F7=0,VLOOKUP(B7,'Рынок+ ИНФО(если не подтягивает'!C:E,3,0),0) -> 0
A8: Алтайский край | B8: Славгород | C8: 78.645913 | D8: 52.999369 | E8: =VLOOKUP(B8,'население 2014'!C:D,2,0) -> 30591 | F8: =VLOOKUP(B8,'Города зп новое (без мск.об)'!B:C,2,0) -> 17514.964 | G8: =IF(F8=0,VLOOKUP(B8,'Рынок+ ИНФО(если не подтягивает'!C:E,3,0),0) -> 0
A9: Алтайский край | B9: Алейск | C9: 82.77943 | D9: 52.492167 | E9: =VLOOKUP(B9,'население 2014'!C:D,2,0) -> 28372 | F9: =VLOOKUP(B9,'Города зп новое (без мск.об)'!B:C,2,0) -> 18944.848 | G9: =IF(F9=0,VLOOKUP(B9,'Рынок+ ИНФО(если не подтягивает'!C:E,3,0),0) -> 0
A10: Алтайский край | B10: Яровое | C10: 78.572916 | D10: 52.925259 | E10: =VLOOKUP(B10,'население 2014'!C:D,2,0) -> #N/A | F10: =VLOOKUP(B10,'Города зп новое (без мск.об)'!B:C,2,0) -> 16843.971 | G10: =IF(F10=0,VLOOKUP(B10,'Рынок+ ИНФО(если не подтягивает'!C:E,3,0),0) -> 0
A11: Алтайский край | B11: Белокуриха | C11: 84.983959 | D11: 51.996094 | E11: =VLOOKUP(B11,'население 2014'!C:D,2,0) -> #N/A | F11: =VLOOKUP(B11,'Города зп новое (без мск.об)'!B:C,2,0) -> 24111.2 | G11: =IF(F11=0,VLOOKUP(B11,'Рынок+ ИНФО(если не подтягивает'!C:E,3,0),0) -> 0
A12: Алтайский край | B12: Горняк | C12: 81.464278 | D12: 50.997899 | E12: =VLOOKUP(B12,'население 2014'!C:D,2,0) -> #N/A | F12: =VLOOKUP(B12,'Города зп новое (без мск.об)'!B:C,2,0) -> 16685.877 | G12: =IF(F12=0,VLOOKUP(B12,'Рынок+ ИНФО(если не подтягивает'!C:E,3,0),0) -> 0
A13: Алтайский край | B13: Змеиногорск | C13: 82.187216 | D13: 51.158122 | E13: =VLOOKUP(B13,'население 2014'!C:D,2,0) -> #N/A | F13: =VLOOKUP(B13,'Города зп новое (без мск.об)'!B:C,2,0) -> 16795.401 | G13: =IF(F13=0,VLOOKUP(B13,'Рынок+ ИНФО(если не подтягивает'!C:E,3,0),0) -> 0
... A1068: Чукотский автономный округ | B1068: Певек | C1068: 170.299935 | D1068: 69.701761 | E1068: =VLOOKUP(B1068,'население 2014'!C:D,2,0) -> #N/A | F1068: =VLOOKUP(B1068,'Города зп новое (без мск.об)'!B:C,2,0) -> 63862.801 | G1068: =IF(F1068=0,VLOOKUP(B1068,'Рынок+ ИНФО(если не подтягивает'!C:E,3,0),0) -> 0
